Workbook

Sheet 표지
C2: 체리부로 26회차 (82.8회차)
C4: 입추일 | D4: 46060
C5: 출하일 | D5: =D4+29 -> 46089
C7: 1동 | D7: 38000
C8: 2동 | D8: 38000
C9: 3동 | D9: 38000
C10: 4동 | D10: 38000
C11: 5동 | D11: 38000
C12: 6동 | D12: 38000
C13: 7동 | D13: 30000
C14: 8동 | D14: 32000
C16: 입추수수 | D16: 280000
C17: 출하수수 | D17: ='1'!H37+'2'!H37+'4'!H37+'6'!H37 -> 294460
C18: 육 성 율 | D18: =D17/D16 -> 1.0516429
C20: 출하중량 | D20: ='1'!G37+'2'!G37+'4'!G37+'6'!G37 -> 497110
C21: 사 료 량 | D21: 659110
C22: 요 구 율 | D22: =D21/D20 -> 1.3258836
C24: 평균체중 | D24: =D20/D17 -> 1.6882089
C25: 사육일수 | D25: =일령!E9 -> 29.654486
C26: 생산지수 | D26: =(D18*D24*100)*100/(D25*D22) -> 451.54253
C28: 농 장 명 | D28: 공암산성
C29: 농장식별번호 | D29: 802615
C30: 농장고유번호 | D30: MMLQL

Sheet 접종
B2: 뉴 캣 슬 병 예 방 접 종 확 인 서
B3: 농 장 명 | C3: 공 암 산 성 | E3: 대 표 자 | F3: 윤 은 희
B4: 소 재 지 | C4: 경남 합천군 용주면 공암길 245-260 | E4: 주민등록번호 | F4: 671103-2332825
B5: 가금의 종류 | C5: 닭 (육계) | E5: H.P | F5: 010-8643-8959
B6: 출하예정일 | C6: =TODAY() -> 46088 | D6: 출 하 처 | E6: 체리부로 | F6: 전화번호
B7: 접 종 횟 수 | C7: 접종일자 | D7: 예방약종류 | E7: 제조업체명 | F7: 접종방법 | G7: 접종수수
B8: 1차 | C8: =표지!D4 -> 46060 | D8: BN++ | E8: 고려B&P | F8: 분무 | G8: =표지!D16 -> 280000
B9: 2차 | C9: =표지!D4+12 -> 46072 | D9: Check ND | E9: (주)코미팜 | F9: 음수 | G9: =표지!D16 -> 280000
B10: 3차
B11: 4차
B12: 상기 가금은 가축전염병예방법 제15조에 따라 예방접종 하였음을 확인합니다.
E13: =C6 -> 46088
D14: 확인자(소유자)등 | F14: 윤 은 희
B15: 절식 확인서
B16: ※ 절식 실시여부를 확인하기 위하여 도축검사의뢰에 따른 제출 서류입니다.
B17: 접수번호 | E17: 접수일 | F17: 처리기간 즉시
B18: 신청내용 | C18: 가축의 종류 (품종) | E18: 총수량 | F18: 절식 시작 일시
C19: 닭 (육계) | E19: 87000 | F19: 2026년 01월 22일 15시
B21: 「축산물 위생관리법」 제12조의2제1항, 같은 법 시행규칙 제18조의2제1항에 따라 위와 같이 가축을도축장에 출하하기
B22: 전에 절식을 실시하였음을 확인합니다.
F23: =C6 -> 46088
B24: 가축을 사육한 자 | F24: 공암산성 윤은희
B25: 가축을 사육한 자가 위와 같이 절식을 실시하였음을 확인합니다.
F26: 년 월 일
B27: 가축을 도축장에 출하하는 자 | F27: (서명 또는 인)
B28: (주) 체리부로 도축장 귀하
B29: 작 성 방 법
B30: 1접수번호 및 접수일은 도축장영업자가 작성합니다. 2. 가축의 종류는 소(한우ㆍ젖소ㆍ육우ㆍ수입소), 돼지, 닭, 오리 등으로 작성합니다. 3. 절식 시작 일시는가축을 도축장에 출하하기 전에 사료급여를 중지한 일시를작성합니다. (예) 2016. 3. 23. 09:00 * 관련 규정 : 가축을 도축장에 출하하기 전 12시간 이상 절식(絶食)할 것. 다만, 가금류는 3시간 이상으로 하며, 물은 제외 4. 절식 시작 일시는 가축을 사육한 자가 기재합니다. 5. 가축을 사육한 자와 가축을 도축장에 출하하는 자가 같은 경우에는 가축을 사육한 자가 모두 확인 서명합니다. 6. 가축을 사육한 자와 가축을 도축장에 출하하는 자가 다른 경우에는 반드시 각자 확인 서명합니다. 7. 계열화사업자의 경우 가축을 도축장에 출하하는 자는 농장관리 책임자 또는 담당자 등이 확인 서명합니다.

Sheet 1
B2: 체리부로 26회차 출하 집계표 | L2: 체리부로 23회차 출하 집계표
B4: 46041 | F4: 27 | G4: 일령 | H4: 1.43 | I4: Kg
B6: 순번 | C6: 차량 | D6: 공차 | E6: 총중량 | F6: 기사 | G6: 중량 | H6: 수수 | I6: 평체 | J6: 계사 | K6: 소독 | L6: 비고
B7: 1 | C7: 7126 | D7: 8140 | E7: 12735 | F7: =IF(C7<>"",VLOOKUP(C7,명단!$C$4:$F$90,2,FALSE),"") -> 전대권 | G7: =IF(E7="","",E7-D7) -> 4595 | H7: 3000 | I7: =IF(G7<>"",G7/H7,"") -> 1.5316667 | J7: 8 | K7: =IF(C7<>"","완료","") -> 완료 | N7: 계량증명서
B8: =B7+1 -> 2 | C8: 5870 | D8: 7885 | E8: 12500 | F8: =IF(C8<>"",VLOOKUP(C8,명단!$C$4:$F$90,2,FALSE),"") -> 홍석희 | G8: =IF(E8="","",E8-D8) -> 4615 | H8: =IF(G8<>"",$H$7,"") -> 3000 | I8: =IF(G8<>"",G8/H8,"") -> 1.5383333 | J8: 8 | K8: =IF(C8<>"","완료","") -> 완료
B9: =B8+1 -> 3 | C9: 6708 | D9: 8720 | E9: 13330 | F9: =IF(C9<>"",VLOOKUP(C9,명단!$C$4:$F$90,2,FALSE),"") -> 김성훈 | G9: =IF(E9="","",E9-D9) -> 4610 | H9: =IF(G9<>"",$H$7,"") -> 3000 | I9: =IF(G9<>"",G9/H9,"") -> 1.5366667 | J9: 8 | K9: =IF(C9<>"","완료","") -> 완료 | N9: (제출용)
B10: =B9+1 -> 4 | C10: 6219 | D10: 8465 | E10: 12880 | F10: =IF(C10<>"",VLOOKUP(C10,명단!$C$4:$F$90,2,FALSE),"") -> 김흥수 | G10: =IF(E10="","",E10-D10) -> 4415 | H10: =IF(G10<>"",$H$7,"") -> 3000 | I10: =IF(G10<>"",G10/H10,"") -> 1.4716667 | J10: 7 | K10: =IF(C10<>"","완료","") -> 완료 | N10: 계량일시 | O10: =NOW() -> 46088.592
B11: =B10+1 -> 5 | C11: 7609 | D11: 8175 | E11: 12560 | F11: =IF(C11<>"",VLOOKUP(C11,명단!$C$4:$F$90,2,FALSE),"") -> 홍은택 | G11: =IF(E11="","",E11-D11) -> 4385 | H11: =IF(G11<>"",$H$7,"") -> 3000 | I11: =IF(G11<>"",G11/H11,"") -> 1.4616667 | J11: 7 | K11: =IF(C11<>"","완료","") -> 완료 | N11: 차량 | O11: =C39 -> 8712 | P11: 기사명 | Q11: =VLOOKUP(O11,C7:I36,4,0) -> 임종웅
B12: =B11+1 -> 6 | C12: 7030 | D12: 8625 | E12: 13030 | F12: =IF(C12<>"",VLOOKUP(C12,명단!$C$4:$F$90,2,FALSE),"") -> 이재철 | G12: =IF(E12="","",E12-D12) -> 4405 | H12: =IF(G12<>"",$H$7,"") -> 3000 | I12: =IF(G12<>"",G12/H12,"") -> 1.4683333 | J12: 7 | K12: =IF(C12<>"","완료","") -> 완료 | N12: 거 래 처 | O12: 체리부로
B13: =B12+1 -> 7 | C13: 6524 | D13: 8590 | E13: 13075 | F13: =IF(C13<>"",VLOOKUP(C13,명단!$C$4:$F$90,2,FALSE),"") -> 김호찬 | G13: =IF(E13="","",E13-D13) -> 4485 | H13: =IF(G13<>"",$H$7,"") -> 3000 | I13: =IF(G13<>"",G13/H13,"") -> 1.495 | J13: 1 | K13: =IF(C13<>"","완료","") -> 완료 | N13: 품명 | O13: 육계
B14: =B13+1 -> 8 | C14: 4440 | D14: 8790 | E14: 13370 | F14: =IF(C14<>"",VLOOKUP(C14,명단!$C$4:$F$90,2,FALSE),"") -> 김성용 | G14: =IF(E14="","",E14-D14) -> 4580 | H14: =IF(G14<>"",$H$7,"") -> 3000 | I14: =IF(G14<>"",G14/H14,"") -> 1.5266667 | J14: 1 | K14: =IF(C14<>"","완료","") -> 완료 | N14: 공차중량 | O14: =VLOOKUP(O11,C7:I36,2,0) -> 8295 | Q14: Kg
B15: =B14+1 -> 9 | C15: 8383 | D15: 8695 | E15: 13165 | F15: =IF(C15<>"",VLOOKUP(C15,명단!$C$4:$F$90,2,FALSE),"") -> 엄정섭 | G15: =IF(E15="","",E15-D15) -> 4470 | H15: =IF(G15<>"",$H$7,"") -> 3000 | I15: =IF(G15<>"",G15/H15,"") -> 1.49 | J15: 1 | K15: =IF(C15<>"","완료","") -> 완료 | N15: 총 중 량 | O15: =VLOOKUP(O11,C7:I36,3,0) -> 12720 | Q15: Kg
B16: =B15+1 -> 10 | C16: 6282 | D16: 8665 | E16: 13135 | F16: =IF(C16<>"",VLOOKUP(C16,명단!$C$4:$F$90,2,FALSE),"") -> 이성재 | G16: =IF(E16="","",E16-D16) -> 4470 | H16: =IF(G16<>"",$H$7,"") -> 3000 | I16: =IF(G16<>"",G16/H16,"") -> 1.49 | J16: 1 | K16: =IF(C16<>"","완료","") -> 완료 | N16: 실 중 량 | O16: =VLOOKUP(O11,C7:I36,5,0) -> 4425 | Q16: Kg
B17: =B16+1 -> 11 | C17: 4230 | D17: 8235 | E17: 12650 | F17: =IF(C17<>"",VLOOKUP(C17,명단!$C$4:$F$90,2,FALSE),"") -> 김은석 | G17: =IF(E17="","",E17-D17) -> 4415 | H17: =IF(G17<>"",$H$7,"") -> 3000 | I17: =IF(G17<>"",G17/H17,"") -> 1.4716667 | J17: 2 | K17: =IF(C17<>"","완료","") -> 완료 | N17: 평체 | O17: =VLOOKUP(O11,C7:I36,7,0) -> 1.475 | Q17: Kg
B18: =B17+1 -> 12 | C18: 1992 | D18: 8310 | E18: 12795 | F18: =IF(C18<>"",VLOOKUP(C18,명단!$C$4:$F$90,2,FALSE),"") -> 왕상만 | G18: =IF(E18="","",E18-D18) -> 4485 | H18: =IF(G18<>"",$H$7,"") -> 3000 | I18: =IF(G18<>"",G18/H18,"") -> 1.495 | J18: 2 | K18: =IF(C18<>"","완료","") -> 완료 | N18: 수수 | O18: =VLOOKUP(O11,C7:I36,6,0) -> 3000 | Q18: 수
B19: =B18+1 -> 13 | C19: 6456 | D19: 8525 | E19: 12925 | F19: =IF(C19<>"",VLOOKUP(C19,명단!$C$4:$F$90,2,FALSE),"") -> 임재경 | G19: =IF(E19="","",E19-D19) -> 4400 | H19: =IF(G19<>"",$H$7,"") -> 3000 | I19: =IF(G19<>"",G19/H19,"") -> 1.4666667 | J19: 2 | K19: =IF(C19<>"","완료","") -> 완료
B20: =B19+1 -> 14 | C20: 8712 | D20: 8295 | E20: 12720 | F20: =IF(C20<>"",VLOOKUP(C20,명단!$C$4:$F$90,2,FALSE),"") -> 임종웅 | G20: =IF(E20="","",E20-D20) -> 4425 | H20: =IF(G20<>"",$H$7,"") -> 3000 | I20: =IF(G20<>"",G20/H20,"") -> 1.475 | J20: 2 | K20: =IF(C20<>"","완료","") -> 완료 | N20: 상기와 같이 계량하였음을 증명함.
F21: =IF(C21<>"",VLOOKUP(C21,명단!$C$4:$F$90,2,FALSE),"") | G21: =IF(E21="","",E21-D21) | H21: =IF(G21<>"",$H$7,"") | I21: =IF(G21<>"",G21/H21,"") | K21: =IF(C21<>"","완료","")
F22: =IF(C22<>"",VLOOKUP(C22,명단!$C$4:$F$90,2,FALSE),"") | G22: =IF(E22="","",E22-D22) | H22: =IF(G22<>"",$H$7,"") | I22: =IF(G22<>"",G22/H22,"") | K22: =IF(C22<>"","완료","") | N22: 공암산성 윤은희
F23: =IF(C23<>"",VLOOKUP(C23,명단!$C$4:$F$90,2,FALSE),"") | G23: =IF(E23="","",E23-D23) | H23: =IF(G23<>"",$H$7,"") | I23: =IF(G23<>"",G23/H23,"") | K23: =IF(C23<>"","완료","")
F24: =IF(C24<>"",VLOOKUP(C24,명단!$C$4:$F$90,2,FALSE),"") | G24: =IF(E24="","",E24-D24) | H24: =IF(G24<>"",$H$7,"") | I24: =IF(G24<>"",G24/H24,"") | K24: =IF(C24<>"","완료","") | N24: 경남 합천군 용주면 공암길 245-260
F25: =IF(C25<>"",VLOOKUP(C25,명단!$C$4:$F$90,2,FALSE),"") | G25: =IF(E25="","",E25-D25) | H25: =IF(G25<>"",$H$7,"") | I25: =IF(G25<>"",G25/H25,"") | K25: =IF(C25<>"","완료","")
F26: =IF(C26<>"",VLOOKUP(C26,명단!$C$4:$F$90,2,FALSE),"") | G26: =IF(E26="","",E26-D26) | H26: =IF(G26<>"",$H$7,"") | I26: =IF(G26<>"",G26/H26,"") | K26: =IF(C26<>"","완료","") | N26: 010-8643-8959,FAX(070)4015-3999
F27: =IF(C27<>"",VLOOKUP(C27,명단!$C$4:$F$90,2,FALSE),"") | G27: =IF(E27="","",E27-D27) | H27: =IF(G27<>"",$H$7,"") | I27: =IF(G27<>"",G27/H27,"") | K27: =IF(C27<>"","완료","")
F28: =IF(C28<>"",VLOOKUP(C28,명단!$C$4:$F$90,2,FALSE),"") | G28: =IF(E28="","",E28-D28) | H28: =IF(G28<>"",$H$7,"") | I28: =IF(G28<>"",G28/H28,"") | K28: =IF(C28<>"","완료","")
F29: =IF(C29<>"",VLOOKUP(C29,명단!$C$4:$F$90,2,FALSE),"") | G29: =IF(E29="","",E29-D29) | H29: =IF(G29<>"",$H$7,"") | I29: =IF(G29<>"",G29/H29,"") | K29: =IF(C29<>"","완료","")
F30: =IF(C30<>"",VLOOKUP(C30,명단!$C$4:$F$90,2,FALSE),"") | G30: =IF(E30="","",E30-D30) | H30: =IF(G30<>"",$H$7,"") | I30: =IF(G30<>"",G30/H30,"") | K30: =IF(C30<>"","완료","")
F31: =IF(C31<>"",VLOOKUP(C31,명단!$C$4:$F$90,2,FALSE),"") | G31: =IF(E31="","",E31-D31) | H31: =IF(G31<>"",$H$7,"") | I31: =IF(G31<>"",G31/H31,"") | K31: =IF(C31<>"","완료","")
F32: =IF(C32<>"",VLOOKUP(C32,명단!$C$4:$F$90,2,FALSE),"") | G32: =IF(E32="","",E32-D32) | H32: =IF(G32<>"",$H$7,"") | I32: =IF(G32<>"",G32/H32,"") | K32: =IF(C32<>"","완료","")
F33: =IF(C33<>"",VLOOKUP(C33,명단!$C$4:$F$90,2,FALSE),"") | G33: =IF(E33="","",E33-D33) | H33: =IF(G33<>"",$H$7,"") | I33: =IF(G33<>"",G33/H33,"") | K33: =IF(C33<>"","완료","")
F34: =IF(C34<>"",VLOOKUP(C34,명단!$C$4:$F$90,2,FALSE),"") | G34: =IF(E34="","",E34-D34) | H34: =IF(G34<>"",$H$7,"") | I34: =IF(G34<>"",G34/H34,"") | K34: =IF(C34<>"","완료","")
F35: =IF(C35<>"",VLOOKUP(C35,명단!$C$4:$F$90,2,FALSE),"") | H35: =IF(G35<>"",$H$7,"") | I35: =IF(G35<>"",G35/H35,"")
F36: =IF(C36<>"",VLOOKUP(C36,명단!$C$4:$F$90,2,FALSE),"") | H36: =IF(G36<>"",$H$7,"") | I36: =IF(G36<>"",G36/H36,"")
B37: 합계 | G37: =SUM(G7:G36) -> 62755 | H37: =SUM(H7:H36) -> 42000 | I37: =IF(H37<>0,G37/H37,0) -> 1.4941667
B39: 인쇄 | C39: 8712

Sheet 2
B2: ='1'!B2 -> 체리부로 26회차 출하 집계표 | L2: 체리부로 23회차 출하 집계표
B4: 46042 | F4: 28 | G4: 일령 | H4: 1.49 | I4: Kg
B6: 순번 | C6: 차량 | D6: 공차 | E6: 총중량 | F6: 기사 | G6: 중량 | H6: 수수 | I6: 평체 | J6: 계사 | K6: 소독 | L6: 비고
B7: 1 | C7: 7202 | D7: 8780 | E7: 13095 | F7: =IF(C7<>"",VLOOKUP(C7,명단!$C$4:$F$90,2,FALSE),"") -> 김길식 | G7: =IF(E7="","",E7-D7) -> 4315 | H7: 2850 | I7: =IF(G7<>"",G7/H7,"") -> 1.5140351 | J7: 3 | K7: =IF(C7<>"","완료","") -> 완료 | N7: 계량증명서
B8: =B7+1 -> 2 | C8: 5755 | D8: 8675 | E8: 12965 | F8: =IF(C8<>"",VLOOKUP(C8,명단!$C$4:$F$90,2,FALSE),"") -> 남세윤 | G8: =IF(E8="","",E8-D8) -> 4290 | H8: =IF(G8<>"",$H$7,"") -> 2850 | I8: =IF(G8<>"",G8/H8,"") -> 1.5052632 | J8: 3 | K8: =IF(C8<>"","완료","") -> 완료
B9: =B8+1 -> 3 | C9: 5673 | D9: 8610 | E9: 12880 | F9: =IF(C9<>"",VLOOKUP(C9,명단!$C$4:$F$90,2,FALSE),"") -> 주성돈 | G9: =IF(E9="","",E9-D9) -> 4270 | H9: =IF(G9<>"",$H$7,"") -> 2850 | I9: =IF(G9<>"",G9/H9,"") -> 1.4982456 | J9: 3 | K9: =IF(C9<>"","완료","") -> 완료 | N9: (제출용)
B10: =B9+1 -> 4 | C10: 5562 | D10: 8060 | E10: 12485 | F10: =IF(C10<>"",VLOOKUP(C10,명단!$C$4:$F$90,2,FALSE),"") -> 오완수 | G10: =IF(E10="","",E10-D10) -> 4425 | H10: =IF(G10<>"",$H$7,"") -> 2850 | I10: =IF(G10<>"",G10/H10,"") -> 1.5526316 | J10: 4 | K10: =IF(C10<>"","완료","") -> 완료 | N10: 계량일시 | O10: =NOW() -> 46088.592
B11: =B10+1 -> 5 | C11: 7030 | D11: 8615 | E11: 12985 | F11: =IF(C11<>"",VLOOKUP(C11,명단!$C$4:$F$90,2,FALSE),"") -> 이재철 | G11: =IF(E11="","",E11-D11) -> 4370 | H11: =IF(G11<>"",$H$7,"") -> 2850 | I11: =IF(G11<>"",G11/H11,"") -> 1.5333333 | J11: 4 | K11: =IF(C11<>"","완료","") -> 완료 | N11: 차량 | O11: =C39 -> 2504 | P11: 기사명 | Q11: =VLOOKUP(O11,C7:I36,4,0) -> 김법규
B12: =B11+1 -> 6 | C12: 3758 | D12: 8255 | E12: 12600 | F12: =IF(C12<>"",VLOOKUP(C12,명단!$C$4:$F$90,2,FALSE),"") -> 강대영 | G12: =IF(E12="","",E12-D12) -> 4345 | H12: =IF(G12<>"",$H$7,"") -> 2850 | I12: =IF(G12<>"",G12/H12,"") -> 1.5245614 | J12: 4 | K12: =IF(C12<>"","완료","") -> 완료 | N12: 거 래 처 | O12: 체리부로
B13: =B12+1 -> 7 | C13: 8809 | D13: 8700 | E13: 13125 | F13: =IF(C13<>"",VLOOKUP(C13,명단!$C$4:$F$90,2,FALSE),"") -> 양승달 | G13: =IF(E13="","",E13-D13) -> 4425 | H13: =IF(G13<>"",$H$7,"") -> 2850 | I13: =IF(G13<>"",G13/H13,"") -> 1.5526316 | J13: 5 | K13: =IF(C13<>"","완료","") -> 완료 | N13: 품명 | O13: 육계
B14: =B13+1 -> 8 | C14: 1267 | D14: 8645 | E14: 13070 | F14: =IF(C14<>"",VLOOKUP(C14,명단!$C$4:$F$90,2,FALSE),"") -> 김용규 | G14: =IF(E14="","",E14-D14) -> 4425 | H14: =IF(G14<>"",$H$7,"") -> 2850 | I14: =IF(G14<>"",G14/H14,"") -> 1.5526316 | J14: 5 | K14: =IF(C14<>"","완료","") -> 완료 | N14: 공차중량 | O14: =VLOOKUP(O11,C7:I36,2,0) -> 8575 | Q14: Kg
B15: =B14+1 -> 9 | C15: 2565 | D15: 8615 | E15: 13040 | F15: =IF(C15<>"",VLOOKUP(C15,명단!$C$4:$F$90,2,FALSE),"") -> 심재응 | G15: =IF(E15="","",E15-D15) -> 4425 | H15: =IF(G15<>"",$H$7,"") -> 2850 | I15: =IF(G15<>"",G15/H15,"") -> 1.5526316 | J15: 5 | K15: =IF(C15<>"","완료","") -> 완료 | N15: 총 중 량 | O15: =VLOOKUP(O11,C7:I36,3,0) -> 12870 | Q15: Kg
B16: =B15+1 -> 10 | C16: 5704 | D16: 8700 | E16: 12950 | F16: =IF(C16<>"",VLOOKUP(C16,명단!$C$4:$F$90,2,FALSE),"") -> 정윤영 | G16: =IF(E16="","",E16-D16) -> 4250 | H16: =IF(G16<>"",$H$7,"") -> 2850 | I16: =IF(G16<>"",G16/H16,"") -> 1.4912281 | J16: 6 | K16: =IF(C16<>"","완료","") -> 완료 | N16: 실 중 량 | O16: =VLOOKUP(O11,C7:I36,5,0) -> 4295 | Q16: Kg
B17: =B16+1 -> 11 | C17: 5911 | D17: 8560 | E17: 12825 | F17: =IF(C17<>"",VLOOKUP(C17,명단!$C$4:$F$90,2,FALSE),"") -> 손길수 | G17: =IF(E17="","",E17-D17) -> 4265 | H17: =IF(G17<>"",$H$7,"") -> 2850 | I17: =IF(G17<>"",G17/H17,"") -> 1.4964912 | J17: 6 | K17: =IF(C17<>"","완료","") -> 완료 | N17: 평체 | O17: =VLOOKUP(O11,C7:I36,7,0) -> 1.5070175 | Q17: Kg
B18: =B17+1 -> 12 | C18: 2504 | D18: 8575 | E18: 12870 | F18: =IF(C18<>"",VLOOKUP(C18,명단!$C$4:$F$90,2,FALSE),"") -> 김법규 | G18: =IF(E18="","",E18-D18) -> 4295 | H18: =IF(G18<>"",$H$7,"") -> 2850 | I18: =IF(G18<>"",G18/H18,"") -> 1.5070175 | J18: 6 | K18: =IF(C18<>"","완료","") -> 완료 | N18: 수수 | O18: =VLOOKUP(O11,C7:I36,6,0) -> 2850 | Q18: 수
F19: =IF(C19<>"",VLOOKUP(C19,명단!$C$4:$F$90,2,FALSE),"") | G19: =IF(E19="","",E19-D19) | H19: =IF(G19<>"",$H$7,"") | I19: =IF(G19<>"",G19/H19,"") | K19: =IF(C19<>"","완료","")
F20: =IF(C20<>"",VLOOKUP(C20,명단!$C$4:$F$90,2,FALSE),"") | G20: =IF(E20="","",E20-D20) | H20: =IF(G20<>"",$H$7,"") | I20: =IF(G20<>"",G20/H20,"") | K20: =IF(C20<>"","완료","") | N20: 상기와 같이 계량하였음을 증명함.
F21: =IF(C21<>"",VLOOKUP(C21,명단!$C$4:$F$90,2,FALSE),"") | G21: =IF(E21="","",E21-D21) | H21: =IF(G21<>"",$H$7,"") | I21: =IF(G21<>"",G21/H21,"") | K21: =IF(C21<>"","완료","")
F22: =IF(C22<>"",VLOOKUP(C22,명단!$C$4:$F$90,2,FALSE),"") | G22: =IF(E22="","",E22-D22) | H22: =IF(G22<>"",$H$7,"") | I22: =IF(G22<>"",G22/H22,"") | K22: =IF(C22<>"","완료","") | N22: 공암산성 윤은희
F23: =IF(C23<>"",VLOOKUP(C23,명단!$C$4:$F$90,2,FALSE),"") | G23: =IF(E23="","",E23-D23) | H23: =IF(G23<>"",$H$7,"") | I23: =IF(G23<>"",G23/H23,"") | K23: =IF(C23<>"","완료","")
F24: =IF(C24<>"",VLOOKUP(C24,명단!$C$4:$F$90,2,FALSE),"") | G24: =IF(E24="","",E24-D24) | H24: =IF(G24<>"",$H$7,"") | I24: =IF(G24<>"",G24/H24,"") | K24: =IF(C24<>"","완료","") | N24: 경남 합천군 용주면 공암길 245-260
F25: =IF(C25<>"",VLOOKUP(C25,명단!$C$4:$F$90,2,FALSE),"") | G25: =IF(E25="","",E25-D25) | H25: =IF(G25<>"",$H$7,"") | I25: =IF(G25<>"",G25/H25,"") | K25: =IF(C25<>"","완료","")
F26: =IF(C26<>"",VLOOKUP(C26,명단!$C$4:$F$90,2,FALSE),"") | G26: =IF(E26="","",E26-D26) | H26: =IF(G26<>"",$H$7,"") | I26: =IF(G26<>"",G26/H26,"") | K26: =IF(C26<>"","완료","") | N26: 010-8643-8959,FAX(070)4015-3999
F27: =IF(C27<>"",VLOOKUP(C27,명단!$C$4:$F$90,2,FALSE),"") | G27: =IF(E27="","",E27-D27) | H27: =IF(G27<>"",$H$7,"") | I27: =IF(G27<>"",G27/H27,"") | K27: =IF(C27<>"","완료","")
F28: =IF(C28<>"",VLOOKUP(C28,명단!$C$4:$F$90,2,FALSE),"") | G28: =IF(E28="","",E28-D28) | H28: =IF(G28<>"",$H$7,"") | I28: =IF(G28<>"",G28/H28,"") | K28: =IF(C28<>"","완료","")
F29: =IF(C29<>"",VLOOKUP(C29,명단!$C$4:$F$90,2,FALSE),"") | G29: =IF(E29="","",E29-D29) | H29: =IF(G29<>"",$H$7,"") | I29: =IF(G29<>"",G29/H29,"") | K29: =IF(C29<>"","완료","")
F30: =IF(C30<>"",VLOOKUP(C30,명단!$C$4:$F$90,2,FALSE),"") | G30: =IF(E30="","",E30-D30) | H30: =IF(G30<>"",$H$7,"") | I30: =IF(G30<>"",G30/H30,"") | K30: =IF(C30<>"","완료","")
F31: =IF(C31<>"",VLOOKUP(C31,명단!$C$4:$F$90,2,FALSE),"") | G31: =IF(E31="","",E31-D31) | H31: =IF(G31<>"",$H$7,"") | I31: =IF(G31<>"",G31/H31,"") | K31: =IF(C31<>"","완료","")
F32: =IF(C32<>"",VLOOKUP(C32,명단!$C$4:$F$90,2,FALSE),"") | G32: =IF(E32="","",E32-D32) | H32: =IF(G32<>"",$H$7,"") | I32: =IF(G32<>"",G32/H32,"") | K32: =IF(C32<>"","완료","")
F33: =IF(C33<>"",VLOOKUP(C33,명단!$C$4:$F$90,2,FALSE),"") | G33: =IF(E33="","",E33-D33) | H33: =IF(G33<>"",$H$7,"") | I33: =IF(G33<>"",G33/H33,"") | K33: =IF(C33<>"","완료","")
F34: =IF(C34<>"",VLOOKUP(C34,명단!$C$4:$F$90,2,FALSE),"") | G34: =IF(E34="","",E34-D34) | H34: =IF(G34<>"",$H$7,"") | I34: =IF(G34<>"",G34/H34,"") | K34: =IF(C34<>"","완료","")
F35: =IF(C35<>"",VLOOKUP(C35,명단!$C$4:$F$90,2,FALSE),"") | H35: =IF(G35<>"",$H$7,"")
F36: =IF(C36<>"",VLOOKUP(C36,명단!$C$4:$F$90,2,FALSE),"") | H36: =IF(G36<>"",$H$7,"")
B37: 합계 | G37: =SUM(G7:G36) -> 52100 | H37: =SUM(H7:H36) -> 34200 | I37: =IF(H37<>0,G37/H37,0) -> 1.5233918
B39: 인쇄 | C39: 2504

Sheet 3
B2: ='1'!B2 -> 체리부로 26회차 출하 집계표 | L2: 체리부로 23회차 출하 집계표
B4: 46044 | F4: 30 | G4: 일령 | H4: 1.75 | I4: Kg
B6: 순번 | C6: 차량 | D6: 공차 | E6: 총중량 | F6: 기사 | G6: 중량 | H6: 수수 | I6: 평체 | J6: 계사 | K6: 소독 | L6: 비고
B7: 1 | C7: 2419 | D7: 9010 | E7: 14660 | F7: 염상혁 | G7: =IF(E7="","",E7-D7) -> 5650 | H7: 3000 | I7: =IF(G7<>"",G7/H7,"") -> 1.8833333 | J7: 8 | K7: =IF(C7<>"","완료","") -> 완료 | L7: 윌푸드 | N7: 계량증명서
B8: =B7+1 -> 2 | C8: 5599 | D8: 7760 | E8: 13455 | F8: 김성삼 | G8: =IF(E8="","",E8-D8) -> 5695 | H8: =IF(G8<>"",$H$7,"") -> 3000 | I8: =IF(G8<>"",G8/H8,"") -> 1.8983333 | J8: 8 | K8: =IF(C8<>"","완료","") -> 완료 | L8: 윌푸드
B9: =B8+1 -> 3 | C9: 5007 | D9: 9240 | E9: 14900 | F9: 장진국 | G9: =IF(E9="","",E9-D9) -> 5660 | H9: =IF(G9<>"",$H$7,"") -> 3000 | I9: =IF(G9<>"",G9/H9,"") -> 1.8866667 | J9: 8 | K9: =IF(C9<>"","완료","") -> 완료 | L9: 금보 | N9: (제출용)
B10: =B9+1 -> 4 | C10: 5343 | D10: 9475 | E10: 15030 | F10: 노종석 | G10: =IF(E10="","",E10-D10) -> 5555 | H10: =IF(G10<>"",$H$7,"") -> 3000 | I10: =IF(G10<>"",G10/H10,"") -> 1.8516667 | J10: 8 | K10: =IF(C10<>"","완료","") -> 완료 | L10: 금보 | N10: 계량일시 | O10: =NOW() -> 46088.592
B11: =B10+1 -> 5 | C11: 9266 | D11: 8575 | E11: 14280 | F11: 허계동 | G11: =IF(E11="","",E11-D11) -> 5705 | H11: =IF(G11<>"",$H$7,"") -> 3000 | I11: =IF(G11<>"",G11/H11,"") -> 1.9016667 | J11: 8 | K11: =IF(C11<>"","완료","") -> 완료 | L11: 금보 | N11: 차량 | O11: =C39 -> 5615 | P11: 기사명 | Q11: =VLOOKUP(O11,C7:I36,4,0) -> 소기복
B12: =B11+1 -> 6 | C12: 8495 | D12: 8465 | E12: 14715 | F12: 송은욱 | G12: =IF(E12="","",E12-D12) -> 6250 | H12: 3200 | I12: =IF(G12<>"",G12/H12,"") -> 1.953125 | J12: 8 | K12: =IF(C12<>"","완료","") -> 완료 | L12: 청도 | N12: 거 래 처 | O12: 체리부로
B13: =B12+1 -> 7 | C13: 7197 | D13: 8220 | E13: 13655 | F13: 김순천 | G13: =IF(E13="","",E13-D13) -> 5435 | H13: =IF(G13<>"",$H$7,"") -> 3000 | I13: =IF(G13<>"",G13/H13,"") -> 1.8116667 | J13: 8 | K13: =IF(C13<>"","완료","") -> 완료 | L13: 청도 | N13: 품명 | O13: 육계
B14: =B13+1 -> 8 | C14: 6790 | D14: 7905 | E14: 13785 | F14: 이종봉 | G14: =IF(E14="","",E14-D14) -> 5880 | H14: 3240 | I14: =IF(G14<>"",G14/H14,"") -> 1.8148148 | J14: 8/7 | K14: =IF(C14<>"","완료","") -> 완료 | L14: 청도 | N14: 공차중량 | O14: =VLOOKUP(O11,C7:I36,2,0) -> 8760 | Q14: Kg
B15: =B14+1 -> 9 | C15: 2914 | D15: 8690 | E15: 13090 | F15: =IF(C15<>"",VLOOKUP(C15,명단!$C$4:$F$90,2,FALSE),"") -> 홍월식 | G15: =IF(E15="","",E15-D15) -> 4400 | H15: 2480 | I15: =IF(G15<>"",G15/H15,"") -> 1.7741935 | J15: 7 | K15: =IF(C15<>"","완료","") -> 완료 | N15: 총 중 량 | O15: =VLOOKUP(O11,C7:I36,3,0) -> 13130 | Q15: Kg
B16: =B15+1 -> 10 | C16: 6797 | D16: 8310 | E16: 12725 | F16: =IF(C16<>"",VLOOKUP(C16,명단!$C$4:$F$90,2,FALSE),"") -> 엄익수 | G16: =IF(E16="","",E16-D16) -> 4415 | H16: =IF(G16<>"",$H$15,"") -> 2480 | I16: =IF(G16<>"",G16/H16,"") -> 1.7802419 | J16: 7 | K16: =IF(C16<>"","완료","") -> 완료 | N16: 실 중 량 | O16: =VLOOKUP(O11,C7:I36,5,0) -> 4370 | Q16: Kg
B17: =B16+1 -> 11 | C17: 5619 | D17: 9055 | E17: 13425 | F17: =IF(C17<>"",VLOOKUP(C17,명단!$C$4:$F$90,2,FALSE),"") -> 송승원 | G17: =IF(E17="","",E17-D17) -> 4370 | H17: =IF(G17<>"",$H$15,"") -> 2480 | I17: =IF(G17<>"",G17/H17,"") -> 1.7620968 | J17: 7 | K17: =IF(C17<>"","완료","") -> 완료 | N17: 평체 | O17: =VLOOKUP(O11,C7:I36,7,0) -> 1.7620968 | Q17: Kg
B18: =B17+1 -> 12 | C18: 3447 | D18: 8450 | E18: 12885 | F18: =IF(C18<>"",VLOOKUP(C18,명단!$C$4:$F$90,2,FALSE),"") -> 전봉근 | G18: =IF(E18="","",E18-D18) -> 4435 | H18: =IF(G18<>"",$H$15,"") -> 2480 | I18: =IF(G18<>"",G18/H18,"") -> 1.7883065 | J18: 7 | K18: =IF(C18<>"","완료","") -> 완료 | N18: 수수 | O18: =VLOOKUP(O11,C7:I36,6,0) -> 2480 | Q18: 수
B19: =B18+1 -> 13 | C19: 4550 | D19: 7870 | E19: 12065 | F19: =IF(C19<>"",VLOOKUP(C19,명단!$C$4:$F$90,2,FALSE),"") -> 윤장열 | G19: =IF(E19="","",E19-D19) -> 4195 | H19: =IF(G19<>"",$H$15,"") -> 2480 | I19: =IF(G19<>"",G19/H19,"") -> 1.6915323 | J19: 7 | K19: =IF(C19<>"","완료","") -> 완료
B20: =B19+1 -> 14 | C20: 5658 | D20: 8470 | E20: 12795 | F20: =IF(C20<>"",VLOOKUP(C20,명단!$C$4:$F$90,2,FALSE),"") -> 김낙영 | G20: =IF(E20="","",E20-D20) -> 4325 | H20: =IF(G20<>"",$H$15,"") -> 2480 | I20: =IF(G20<>"",G20/H20,"") -> 1.7439516 | J20: 7 | K20: =IF(C20<>"","완료","") -> 완료 | N20: 상기와 같이 계량하였음을 증명함.
B21: =B20+1 -> 15 | C21: 5831 | D21: 8615 | E21: 12880 | F21: =IF(C21<>"",VLOOKUP(C21,명단!$C$4:$F$90,2,FALSE),"") -> 김주철 | G21: =IF(E21="","",E21-D21) -> 4265 | H21: =IF(G21<>"",$H$15,"") -> 2480 | I21: =IF(G21<>"",G21/H21,"") -> 1.7197581 | J21: 7 | K21: =IF(C21<>"","완료","") -> 완료
B22: =B21+1 -> 16 | C22: 7126 | D22: 8235 | E22: 12555 | F22: =IF(C22<>"",VLOOKUP(C22,명단!$C$4:$F$90,2,FALSE),"") -> 전대권 | G22: =IF(E22="","",E22-D22) -> 4320 | H22: =IF(G22<>"",$H$15,"") -> 2480 | I22: =IF(G22<>"",G22/H22,"") -> 1.7419355 | J22: 7 | K22: =IF(C22<>"","완료","") -> 완료 | N22: 공암산성 윤은희
B23: =B22+1 -> 17 | C23: 1509 | D23: 8045 | E23: 12380 | F23: =IF(C23<>"",VLOOKUP(C23,명단!$C$4:$F$90,2,FALSE),"") -> 김용태 | G23: =IF(E23="","",E23-D23) -> 4335 | H23: =IF(G23<>"",$H$15,"") -> 2480 | I23: =IF(G23<>"",G23/H23,"") -> 1.7479839 | J23: 2 | K23: =IF(C23<>"","완료","") -> 완료
B24: =B23+1 -> 18 | C24: 5870 | D24: 7915 | E24: 12195 | F24: =IF(C24<>"",VLOOKUP(C24,명단!$C$4:$F$90,2,FALSE),"") -> 홍석희 | G24: =IF(E24="","",E24-D24) -> 4280 | H24: =IF(G24<>"",$H$15,"") -> 2480 | I24: =IF(G24<>"",G24/H24,"") -> 1.7258065 | J24: 2 | K24: =IF(C24<>"","완료","") -> 완료 | N24: 경남 합천군 용주면 공암길 245-260
B25: =B24+1 -> 19 | C25: 5755 | D25: 8655 | E25: 12960 | F25: =IF(C25<>"",VLOOKUP(C25,명단!$C$4:$F$90,2,FALSE),"") -> 남세윤 | G25: =IF(E25="","",E25-D25) -> 4305 | H25: =IF(G25<>"",$H$15,"") -> 2480 | I25: =IF(G25<>"",G25/H25,"") -> 1.7358871 | J25: 2 | K25: =IF(C25<>"","완료","") -> 완료
B26: =B25+1 -> 20 | C26: 1340 | D26: 8485 | E26: 12745 | F26: =IF(C26<>"",VLOOKUP(C26,명단!$C$4:$F$90,2,FALSE),"") -> 박근우 | G26: =IF(E26="","",E26-D26) -> 4260 | H26: =IF(G26<>"",$H$15,"") -> 2480 | I26: =IF(G26<>"",G26/H26,"") -> 1.7177419 | J26: 2 | K26: =IF(C26<>"","완료","") -> 완료 | N26: 010-8643-8959,FAX(070)4015-3999
B27: =B26+1 -> 21 | C27: 5673 | D27: 8595 | E27: 12840 | F27: =IF(C27<>"",VLOOKUP(C27,명단!$C$4:$F$90,2,FALSE),"") -> 주성돈 | G27: =IF(E27="","",E27-D27) -> 4245 | H27: =IF(G27<>"",$H$15,"") -> 2480 | I27: =IF(G27<>"",G27/H27,"") -> 1.7116935 | J27: 2 | K27: =IF(C27<>"","완료","") -> 완료
B28: =B27+1 -> 22 | C28: 1294 | D28: 8440 | E28: 12570 | F28: =IF(C28<>"",VLOOKUP(C28,명단!$C$4:$F$90,2,FALSE),"") -> 이병옥 | G28: =IF(E28="","",E28-D28) -> 4130 | H28: =IF(G28<>"",$H$15,"") -> 2480 | I28: =IF(G28<>"",G28/H28,"") -> 1.6653226 | J28: 2 | K28: =IF(C28<>"","완료","") -> 완료
B29: =B28+1 -> 23 | C29: 5562 | D29: 8050 | E29: 12095 | F29: =IF(C29<>"",VLOOKUP(C29,명단!$C$4:$F$90,2,FALSE),"") -> 오완수 | G29: =IF(E29="","",E29-D29) -> 4045 | H29: =IF(G29<>"",$H$15,"") -> 2480 | I29: =IF(G29<>"",G29/H29,"") -> 1.6310484 | J29: 2 | K29: =IF(C29<>"","완료","") -> 완료
B30: =B29+1 -> 24 | C30: 5784 | D30: 7775 | E30: 11700 | F30: =IF(C30<>"",VLOOKUP(C30,명단!$C$4:$F$90,2,FALSE),"") -> 정영천 | G30: =IF(E30="","",E30-D30) -> 3925 | H30: =IF(G30<>"",$H$15,"") -> 2480 | I30: =IF(G30<>"",G30/H30,"") -> 1.5826613 | J30: 2 | K30: =IF(C30<>"","완료","") -> 완료
B31: =B30+1 -> 25 | C31: 6680 | D31: 8515 | E31: 12530 | F31: =IF(C31<>"",VLOOKUP(C31,명단!$C$4:$F$90,2,FALSE),"") -> 신동수 | G31: =IF(E31="","",E31-D31) -> 4015 | H31: =IF(G31<>"",$H$15,"") -> 2480 | I31: =IF(G31<>"",G31/H31,"") -> 1.6189516 | J31: 2 | K31: =IF(C31<>"","완료","") -> 완료
B32: =B31+1 -> 26 | C32: 6762 | D32: 8450 | E32: 12440 | F32: =IF(C32<>"",VLOOKUP(C32,명단!$C$4:$F$90,2,FALSE),"") -> 안준모 | G32: =IF(E32="","",E32-D32) -> 3990 | H32: =IF(G32<>"",$H$15,"") -> 2480 | I32: =IF(G32<>"",G32/H32,"") -> 1.608871 | J32: 2 | K32: =IF(C32<>"","완료","") -> 완료
B33: =B32+1 -> 27 | C33: 6524 | D33: 8635 | E33: 12900 | F33: =IF(C33<>"",VLOOKUP(C33,명단!$C$4:$F$90,2,FALSE),"") -> 김호찬 | G33: =IF(E33="","",E33-D33) -> 4265 | H33: =IF(G33<>"",$H$15,"") -> 2480 | I33: =IF(G33<>"",G33/H33,"") -> 1.7197581 | J33: 2/1 | K33: =IF(C33<>"","완료","") -> 완료
B34: =B33+1 -> 28 | C34: 3758 | D34: 8220 | E34: 12620 | F34: =IF(C34<>"",VLOOKUP(C34,명단!$C$4:$F$90,2,FALSE),"") -> 강대영 | G34: =IF(E34="","",E34-D34) -> 4400 | H34: =IF(G34<>"",$H$15,"") -> 2480 | I34: =IF(G34<>"",G34/H34,"") -> 1.7741935 | J34: 1 | K34: =IF(C34<>"","완료","") -> 완료
B35: =B34+1 -> 29 | C35: 4271 | D35: 8595 | E35: 12970 | F35: =IF(C35<>"",VLOOKUP(C35,명단!$C$4:$F$90,2,FALSE),"") -> 박영길 | G35: =IF(E35="","",E35-D35) -> 4375 | H35: =IF(G35<>"",$H$15,"") -> 2480 | I35: =IF(G35<>"",G35/H35,"") -> 1.7641129 | J35: 1 | K35: =IF(C35<>"","완료","") -> 완료
B36: =B35+1 -> 30 | C36: 5615 | D36: 8760 | E36: 13130 | F36: =IF(C36<>"",VLOOKUP(C36,명단!$C$4:$F$90,2,FALSE),"") -> 소기복 | G36: =IF(E36="","",E36-D36) -> 4370 | H36: =IF(G36<>"",$H$15,"") -> 2480 | I36: =IF(G36<>"",G36/H36,"") -> 1.7620968 | J36: 1 | K36: =IF(C36<>"","완료","") -> 완료
B37: 소계 | G37: =SUM(G7:G36) -> 139495 | H37: =SUM(H7:H36) -> 79000 | I37: =IF(H37<>0,G37/H37,0) -> 1.7657595
B39: 인쇄 | C39: 5615

Sheet 4
B2: ='1'!B2 -> 체리부로 26회차 출하 집계표 | L2: 체리부로 23회차 출하 집계표
B4: 46044 | F4: 30 | G4: 일령 | H4: 1.75 | I4: Kg
B6: 순번 | C6: 차량 | D6: 공차 | E6: 총중량 | F6: 기사 | G6: 중량 | H6: 수수 | I6: 평체 | J6: 계사 | K6: 소독 | L6: 비고
B7: 31 | C7: 5815 | D7: 8590 | E7: 12735 | F7: =IF(C7<>"",VLOOKUP(C7,명단!$C$4:$F$90,2,FALSE),"") -> 김창수 | G7: =IF(E7="","",E7-D7) -> 4145 | H7: 2480 | I7: =IF(G7<>"",G7/H7,"") -> 1.671371 | J7: 1 | K7: =IF(C7<>"","완료","") -> 완료 | N7: 계량증명서
B8: =B7+1 -> 32 | C8: 8809 | D8: 8690 | E8: 12990 | F8: =IF(C8<>"",VLOOKUP(C8,명단!$C$4:$F$90,2,FALSE),"") -> 양승달 | G8: =IF(E8="","",E8-D8) -> 4300 | H8: =IF(G8<>"",$H$7,"") -> 2480 | I8: =IF(G8<>"",G8/H8,"") -> 1.733871 | J8: 1 | K8: =IF(C8<>"","완료","") -> 완료
B9: =B8+1 -> 33 | C9: 1267 | D9: 8635 | E9: 12945 | F9: =IF(C9<>"",VLOOKUP(C9,명단!$C$4:$F$90,2,FALSE),"") -> 김용규 | G9: =IF(E9="","",E9-D9) -> 4310 | H9: =IF(G9<>"",$H$7,"") -> 2480 | I9: =IF(G9<>"",G9/H9,"") -> 1.7379032 | J9: 1 | K9: =IF(C9<>"","완료","") -> 완료 | N9: (제출용)
B10: =B9+1 -> 34 | C10: 2565 | D10: 8720 | E10: 12965 | F10: =IF(C10<>"",VLOOKUP(C10,명단!$C$4:$F$90,2,FALSE),"") -> 심재응 | G10: =IF(E10="","",E10-D10) -> 4245 | H10: =IF(G10<>"",$H$7,"") -> 2480 | I10: =IF(G10<>"",G10/H10,"") -> 1.7116935 | J10: 1 | K10: =IF(C10<>"","완료","") -> 완료 | N10: 계량일시 | O10: =NOW() -> 46088.592
B11: =B10+1 -> 35 | C11: 5704 | D11: 8730 | E11: 12800 | F11: =IF(C11<>"",VLOOKUP(C11,명단!$C$4:$F$90,2,FALSE),"") -> 정윤영 | G11: =IF(E11="","",E11-D11) -> 4070 | H11: =IF(G11<>"",$H$7,"") -> 2480 | I11: =IF(G11<>"",G11/H11,"") -> 1.641129 | J11: 1 | K11: =IF(C11<>"","완료","") -> 완료 | N11: 차량 | O11: =C39 -> 3403 | P11: 기사명 | Q11: =VLOOKUP(O11,C7:I36,4,0) -> 신공식
B12: =B11+1 -> 36 | C12: 5503 | D12: 8690 | E12: 12865 | F12: =IF(C12<>"",VLOOKUP(C12,명단!$C$4:$F$90,2,FALSE),"") -> 채문병 | G12: =IF(E12="","",E12-D12) -> 4175 | H12: =IF(G12<>"",$H$7,"") -> 2480 | I12: =IF(G12<>"",G12/H12,"") -> 1.6834677 | J12: 1 | K12: =IF(C12<>"","완료","") -> 완료 | N12: 거 래 처 | O12: 체리부로
B13: =B12+1 -> 37 | C13: 5957 | D13: 8760 | E13: 12965 | F13: =IF(C13<>"",VLOOKUP(C13,명단!$C$4:$F$90,2,FALSE),"") -> 박현수 | G13: =IF(E13="","",E13-D13) -> 4205 | H13: =IF(G13<>"",$H$7,"") -> 2480 | I13: =IF(G13<>"",G13/H13,"") -> 1.6955645 | J13: 1 | K13: =IF(C13<>"","완료","") -> 완료 | N13: 품명 | O13: 육계
B14: =B13+1 -> 38 | C14: 5911 | D14: 8585 | E14: 12960 | F14: =IF(C14<>"",VLOOKUP(C14,명단!$C$4:$F$90,2,FALSE),"") -> 손길수 | G14: =IF(E14="","",E14-D14) -> 4375 | H14: =IF(G14<>"",$H$7,"") -> 2480 | I14: =IF(G14<>"",G14/H14,"") -> 1.7641129 | J14: 4 | K14: =IF(C14<>"","완료","") -> 완료 | N14: 공차중량 | O14: =VLOOKUP(O11,C7:I36,2,0) -> 8435 | Q14: Kg
B15: =B14+1 -> 39 | C15: 6456 | D15: 8595 | E15: 12840 | F15: =IF(C15<>"",VLOOKUP(C15,명단!$C$4:$F$90,2,FALSE),"") -> 임재경 | G15: =IF(E15="","",E15-D15) -> 4245 | H15: =IF(G15<>"",$H$7,"") -> 2480 | I15: =IF(G15<>"",G15/H15,"") -> 1.7116935 | J15: 4 | K15: =IF(C15<>"","완료","") -> 완료 | N15: 총 중 량 | O15: =VLOOKUP(O11,C7:I36,3,0) -> 11695 | Q15: Kg
B16: =B15+1 -> 40 | C16: 2504 | D16: 8550 | E16: 12835 | F16: =IF(C16<>"",VLOOKUP(C16,명단!$C$4:$F$90,2,FALSE),"") -> 김법규 | G16: =IF(E16="","",E16-D16) -> 4285 | H16: =IF(G16<>"",$H$7,"") -> 2480 | I16: =IF(G16<>"",G16/H16,"") -> 1.7278226 | J16: 4 | K16: =IF(C16<>"","완료","") -> 완료 | N16: 실 중 량 | O16: =VLOOKUP(O11,C7:I36,5,0) -> 3260 | Q16: Kg
B17: =B16+1 -> 41 | C17: 8712 | D17: 8330 | E17: 12595 | F17: =IF(C17<>"",VLOOKUP(C17,명단!$C$4:$F$90,2,FALSE),"") -> 임종웅 | G17: =IF(E17="","",E17-D17) -> 4265 | H17: =IF(G17<>"",$H$7,"") -> 2480 | I17: =IF(G17<>"",G17/H17,"") -> 1.7197581 | J17: 4 | K17: =IF(C17<>"","완료","") -> 완료 | N17: 평체 | O17: =VLOOKUP(O11,C7:I36,7,0) -> 1.6632653 | Q17: Kg
B18: =B17+1 -> 42 | C18: 5879 | D18: 8325 | E18: 12580 | F18: =IF(C18<>"",VLOOKUP(C18,명단!$C$4:$F$90,2,FALSE),"") -> 김기욱 | G18: =IF(E18="","",E18-D18) -> 4255 | H18: =IF(G18<>"",$H$7,"") -> 2480 | I18: =IF(G18<>"",G18/H18,"") -> 1.7157258 | J18: 4 | K18: =IF(C18<>"","완료","") -> 완료 | N18: 수수 | O18: =VLOOKUP(O11,C7:I36,6,0) -> 1960 | Q18: 수
B19: =B18+1 -> 43 | C19: 4451 | D19: 8465 | E19: 12755 | F19: =IF(C19<>"",VLOOKUP(C19,명단!$C$4:$F$90,2,FALSE),"") -> 차동준 | G19: =IF(E19="","",E19-D19) -> 4290 | H19: =IF(G19<>"",$H$7,"") -> 2480 | I19: =IF(G19<>"",G19/H19,"") -> 1.7298387 | J19: 4 | K19: =IF(C19<>"","완료","") -> 완료
B20: =B19+1 -> 44 | C20: 5880 | D20: 8825 | E20: 13115 | F20: =IF(C20<>"",VLOOKUP(C20,명단!$C$4:$F$90,2,FALSE),"") -> 최장열 | G20: =IF(E20="","",E20-D20) -> 4290 | H20: =IF(G20<>"",$H$7,"") -> 2480 | I20: =IF(G20<>"",G20/H20,"") -> 1.7298387 | J20: 4 | K20: =IF(C20<>"","완료","") -> 완료 | N20: 상기와 같이 계량하였음을 증명함.
B21: =B20+1 -> 45 | C21: 1027 | D21: 8230 | E21: 12500 | F21: =IF(C21<>"",VLOOKUP(C21,명단!$C$4:$F$90,2,FALSE),"") -> 안자현 | G21: =IF(E21="","",E21-D21) -> 4270 | H21: =IF(G21<>"",$H$7,"") -> 2480 | I21: =IF(G21<>"",G21/H21,"") -> 1.7217742 | J21: 4 | K21: =IF(C21<>"","완료","") -> 완료
B22: =B21+1 -> 46 | C22: 5021 | D22: 8555 | E22: 12680 | F22: =IF(C22<>"",VLOOKUP(C22,명단!$C$4:$F$90,2,FALSE),"") -> 김영길 | G22: =IF(E22="","",E22-D22) -> 4125 | H22: =IF(G22<>"",$H$7,"") -> 2480 | I22: =IF(G22<>"",G22/H22,"") -> 1.6633065 | J22: 4 | K22: =IF(C22<>"","완료","") -> 완료 | N22: 공암산성 윤은희
B23: =B22+1 -> 47 | C23: 4510 | D23: 8950 | E23: 13135 | F23: =IF(C23<>"",VLOOKUP(C23,명단!$C$4:$F$90,2,FALSE),"") -> 심우철 | G23: =IF(E23="","",E23-D23) -> 4185 | H23: =IF(G23<>"",$H$7,"") -> 2480 | I23: =IF(G23<>"",G23/H23,"") -> 1.6875 | J23: 4 | K23: =IF(C23<>"","완료","") -> 완료
B24: =B23+1 -> 48 | C24: 5579 | D24: 9000 | E24: 13125 | F24: =IF(C24<>"",VLOOKUP(C24,명단!$C$4:$F$90,2,FALSE),"") -> 박승렬 | G24: =IF(E24="","",E24-D24) -> 4125 | H24: =IF(G24<>"",$H$7,"") -> 2480 | I24: =IF(G24<>"",G24/H24,"") -> 1.6633065 | J24: 4 | K24: =IF(C24<>"","완료","") -> 완료 | N24: 경남 합천군 용주면 공암길 245-260
B25: =B24+1 -> 49 | C25: 3403 | D25: 8435 | E25: 11695 | F25: =IF(C25<>"",VLOOKUP(C25,명단!$C$4:$F$90,2,FALSE),"") -> 신공식 | G25: =IF(E25="","",E25-D25) -> 3260 | H25: 1960 | I25: =IF(G25<>"",G25/H25,"") -> 1.6632653 | J25: 4 | K25: =IF(C25<>"","완료","") -> 완료
F26: =IF(C26<>"",VLOOKUP(C26,명단!$C$4:$F$90,2,FALSE),"") | G26: =IF(E26="","",E26-D26) | H26: =IF(G26<>"",$H$7,"") | I26: =IF(G26<>"",G26/H26,"") | K26: =IF(C26<>"","완료","") | N26: 010-8643-8959,FAX(070)4015-3999
F27: =IF(C27<>"",VLOOKUP(C27,명단!$C$4:$F$90,2,FALSE),"") | G27: =IF(E27="","",E27-D27) | H27: =IF(G27<>"",$H$7,"") | I27: =IF(G27<>"",G27/H27,"") | K27: =IF(C27<>"","완료","")
F28: =IF(C28<>"",VLOOKUP(C28,명단!$C$4:$F$90,2,FALSE),"") | G28: =IF(E28="","",E28-D28) | H28: =IF(G28<>"",$H$7,"") | I28: =IF(G28<>"",G28/H28,"") | K28: =IF(C28<>"","완료","")
F29: =IF(C29<>"",VLOOKUP(C29,명단!$C$4:$F$90,2,FALSE),"") | G29: =IF(E29="","",E29-D29) | H29: =IF(G29<>"",$H$7,"") | I29: =IF(G29<>"",G29/H29,"") | K29: =IF(C29<>"","완료","")
F30: =IF(C30<>"",VLOOKUP(C30,명단!$C$4:$F$90,2,FALSE),"") | G30: =IF(E30="","",E30-D30) | H30: =IF(G30<>"",$H$7,"") | I30: =IF(G30<>"",G30/H30,"") | K30: =IF(C30<>"","완료","")
F31: =IF(C31<>"",VLOOKUP(C31,명단!$C$4:$F$90,2,FALSE),"") | G31: =IF(E31="","",E31-D31) | H31: =IF(G31<>"",$H$7,"") | I31: =IF(G31<>"",G31/H31,"") | K31: =IF(C31<>"","완료","")
F32: =IF(C32<>"",VLOOKUP(C32,명단!$C$4:$F$90,2,FALSE),"") | G32: =IF(E32="","",E32-D32) | H32: =IF(G32<>"",$H$7,"") | I32: =IF(G32<>"",G32/H32,"") | K32: =IF(C32<>"","완료","")
F33: =IF(C33<>"",VLOOKUP(C33,명단!$C$4:$F$90,2,FALSE),"") | G33: =IF(E33="","",E33-D33) | H33: =IF(G33<>"",$H$7,"") | I33: =IF(G33<>"",G33/H33,"") | K33: =IF(C33<>"","완료","")
F34: =IF(C34<>"",VLOOKUP(C34,명단!$C$4:$F$90,2,FALSE),"") | G34: =IF(E34="","",E34-D34) | H34: =IF(G34<>"",$H$7,"") | I34: =IF(G34<>"",G34/H34,"") | K34: =IF(C34<>"","완료","")
B35: 소계 | F35: =IF(C35<>"",VLOOKUP(C35,명단!$C$4:$F$90,2,FALSE),"") | G35: =SUM(G7:G25) -> 79420 | H35: =SUM(H7:H25) -> 46600 | I35: =IF(G35<>"",G35/H35,"") -> 1.7042918
F36: =IF(C36<>"",VLOOKUP(C36,명단!$C$4:$F$90,2,FALSE),"") | H36: =IF(G36<>"",$H$7,"")
B37: 합계 | G37: =G35+'3'!G37 -> 218915 | H37: =H35+'3'!H37 -> 125600 | I37: =IF(H37<>0,G37/H37,0) -> 1.7429538
B39: 인쇄 | C39: 3403 | G39: 3260 | H39: =G39/I39 -> 1963.8554 | I39: 1.66

Sheet 5
B2: ='1'!B2 -> 체리부로 26회차 출하 집계표 | L2: 체리부로 23회차 출하 집계표
B4: 46045 | F4: 31 | G4: 일령 | H4: 1.77 | I4: Kg
B6: 순번 | C6: 차량 | D6: 공차 | E6: 총중량 | F6: 기사 | G6: 중량 | H6: 수수 | I6: 평체 | J6: 계사 | K6: 소독 | L6: 비고
B7: 1 | C7: 6524 | D7: 8630 | E7: 13045 | F7: =IF(C7<>"",VLOOKUP(C7,명단!$C$4:$F$90,2,FALSE),"") -> 김호찬 | G7: =IF(E7="","",E7-D7) -> 4415 | H7: 2420 | I7: =IF(G7<>"",G7/H7,"") -> 1.8243802 | J7: 5 | K7: =IF(C7<>"","완료","") -> 완료 | N7: 계량증명서
B8: =B7+1 -> 2 | C8: 4440 | D8: 8785 | E8: 13180 | F8: =IF(C8<>"",VLOOKUP(C8,명단!$C$4:$F$90,2,FALSE),"") -> 김성용 | G8: =IF(E8="","",E8-D8) -> 4395 | H8: =IF(G8<>"",$H$7,"") -> 2420 | I8: =IF(G8<>"",G8/H8,"") -> 1.8161157 | J8: 5 | K8: =IF(C8<>"","완료","") -> 완료
B9: =B8+1 -> 3 | C9: 1267 | D9: 8655 | E9: 13100 | F9: =IF(C9<>"",VLOOKUP(C9,명단!$C$4:$F$90,2,FALSE),"") -> 김용규 | G9: =IF(E9="","",E9-D9) -> 4445 | H9: =IF(G9<>"",$H$7,"") -> 2420 | I9: =IF(G9<>"",G9/H9,"") -> 1.8367769 | J9: 5 | K9: =IF(C9<>"","완료","") -> 완료 | N9: (제출용)
B10: =B9+1 -> 4 | C10: 8383 | D10: 8760 | E10: 13170 | F10: =IF(C10<>"",VLOOKUP(C10,명단!$C$4:$F$90,2,FALSE),"") -> 엄정섭 | G10: =IF(E10="","",E10-D10) -> 4410 | H10: =IF(G10<>"",$H$7,"") -> 2420 | I10: =IF(G10<>"",G10/H10,"") -> 1.822314 | J10: 5 | K10: =IF(C10<>"","완료","") -> 완료 | N10: 계량일시 | O10: =NOW() -> 46088.592
B11: =B10+1 -> 5 | C11: 8809 | D11: 8730 | E11: 13085 | F11: =IF(C11<>"",VLOOKUP(C11,명단!$C$4:$F$90,2,FALSE),"") -> 양승달 | G11: =IF(E11="","",E11-D11) -> 4355 | H11: =IF(G11<>"",$H$7,"") -> 2420 | I11: =IF(G11<>"",G11/H11,"") -> 1.7995868 | J11: 5 | K11: =IF(C11<>"","완료","") -> 완료 | N11: 차량 | O11: =C39 -> 4109 | P11: 기사명 | Q11: =VLOOKUP(O11,C7:I36,4,0) -> 장성조
B12: =B11+1 -> 6 | C12: 6282 | D12: 8695 | E12: 13070 | F12: =IF(C12<>"",VLOOKUP(C12,명단!$C$4:$F$90,2,FALSE),"") -> 이성재 | G12: =IF(E12="","",E12-D12) -> 4375 | H12: =IF(G12<>"",$H$7,"") -> 2420 | I12: =IF(G12<>"",G12/H12,"") -> 1.8078512 | J12: 5 | K12: =IF(C12<>"","완료","") -> 완료 | N12: 거 래 처 | O12: 체리부로
B13: =B12+1 -> 7 | C13: 5815 | D13: 8600 | E13: 12975 | F13: =IF(C13<>"",VLOOKUP(C13,명단!$C$4:$F$90,2,FALSE),"") -> 김창수 | G13: =IF(E13="","",E13-D13) -> 4375 | H13: =IF(G13<>"",$H$7,"") -> 2420 | I13: =IF(G13<>"",G13/H13,"") -> 1.8078512 | J13: 5 | K13: =IF(C13<>"","완료","") -> 완료 | N13: 품명 | O13: 육계
B14: =B13+1 -> 8 | C14: 4230 | D14: 8420 | E14: 12585 | F14: =IF(C14<>"",VLOOKUP(C14,명단!$C$4:$F$90,2,FALSE),"") -> 김은석 | G14: =IF(E14="","",E14-D14) -> 4165 | H14: =IF(G14<>"",$H$7,"") -> 2420 | I14: =IF(G14<>"",G14/H14,"") -> 1.7210744 | J14: 5 | K14: =IF(C14<>"","완료","") -> 완료 | N14: 공차중량 | O14: =VLOOKUP(O11,C7:I36,2,0) -> 8915 | Q14: Kg
B15: =B14+1 -> 9 | C15: 1992 | D15: 8205 | E15: 12455 | F15: =IF(C15<>"",VLOOKUP(C15,명단!$C$4:$F$90,2,FALSE),"") -> 왕상만 | G15: =IF(E15="","",E15-D15) -> 4250 | H15: =IF(G15<>"",$H$7,"") -> 2420 | I15: =IF(G15<>"",G15/H15,"") -> 1.7561983 | J15: 5 | K15: =IF(C15<>"","완료","") -> 완료 | N15: 총 중 량 | O15: =VLOOKUP(O11,C7:I36,3,0) -> 13135 | Q15: Kg
B16: =B15+1 -> 10 | C16: 5957 | D16: 8685 | E16: 12865 | F16: =IF(C16<>"",VLOOKUP(C16,명단!$C$4:$F$90,2,FALSE),"") -> 박현수 | G16: =IF(E16="","",E16-D16) -> 4180 | H16: =IF(G16<>"",$H$7,"") -> 2420 | I16: =IF(G16<>"",G16/H16,"") -> 1.7272727 | J16: 5 | K16: =IF(C16<>"","완료","") -> 완료 | N16: 실 중 량 | O16: =VLOOKUP(O11,C7:I36,5,0) -> 4220 | Q16: Kg
B17: =B16+1 -> 11 | C17: 6456 | D17: 8620 | E17: 12840 | F17: =IF(C17<>"",VLOOKUP(C17,명단!$C$4:$F$90,2,FALSE),"") -> 임재경 | G17: =IF(E17="","",E17-D17) -> 4220 | H17: =IF(G17<>"",$H$7,"") -> 2420 | I17: =IF(G17<>"",G17/H17,"") -> 1.7438017 | J17: 5 | K17: =IF(C17<>"","완료","") -> 완료 | N17: 평체 | O17: =VLOOKUP(O11,C7:I36,7,0) -> 1.7438017 | Q17: Kg
B18: =B17+1 -> 12 | C18: 2504 | D18: 8610 | E18: 12840 | F18: =IF(C18<>"",VLOOKUP(C18,명단!$C$4:$F$90,2,FALSE),"") -> 김법규 | G18: =IF(E18="","",E18-D18) -> 4230 | H18: =IF(G18<>"",$H$7,"") -> 2420 | I18: =IF(G18<>"",G18/H18,"") -> 1.7479339 | J18: 5 | K18: =IF(C18<>"","완료","") -> 완료 | N18: 수수 | O18: =VLOOKUP(O11,C7:I36,6,0) -> 2420 | Q18: 수
B19: =B18+1 -> 13 | C19: 8712 | D19: 8380 | E19: 12680 | F19: =IF(C19<>"",VLOOKUP(C19,명단!$C$4:$F$90,2,FALSE),"") -> 임종웅 | G19: =IF(E19="","",E19-D19) -> 4300 | H19: =IF(G19<>"",$H$7,"") -> 2420 | I19: =IF(G19<>"",G19/H19,"") -> 1.7768595 | J19: 3 | K19: =IF(C19<>"","완료","") -> 완료
B20: =B19+1 -> 14 | C20: 5879 | D20: 8340 | E20: 12665 | F20: =IF(C20<>"",VLOOKUP(C20,명단!$C$4:$F$90,2,FALSE),"") -> 김기욱 | G20: =IF(E20="","",E20-D20) -> 4325 | H20: =IF(G20<>"",$H$7,"") -> 2420 | I20: =IF(G20<>"",G20/H20,"") -> 1.7871901 | J20: 3 | K20: =IF(C20<>"","완료","") -> 완료 | N20: 상기와 같이 계량하였음을 증명함.
B21: =B20+1 -> 15 | C21: 5749 | D21: 8565 | E21: 13015 | F21: =IF(C21<>"",VLOOKUP(C21,명단!$C$4:$F$90,2,FALSE),"") -> 양충환 | G21: =IF(E21="","",E21-D21) -> 4450 | H21: =IF(G21<>"",$H$7,"") -> 2420 | I21: =IF(G21<>"",G21/H21,"") -> 1.838843 | J21: 3 | K21: =IF(C21<>"","완료","") -> 완료
B22: =B21+1 -> 16 | C22: 4451 | D22: 8470 | E22: 12890 | F22: =IF(C22<>"",VLOOKUP(C22,명단!$C$4:$F$90,2,FALSE),"") -> 차동준 | G22: =IF(E22="","",E22-D22) -> 4420 | H22: =IF(G22<>"",$H$7,"") -> 2420 | I22: =IF(G22<>"",G22/H22,"") -> 1.8264463 | J22: 3 | K22: =IF(C22<>"","완료","") -> 완료 | N22: 공암산성 윤은희
B23: =B22+1 -> 17 | C23: 5880 | D23: 8760 | E23: 13205 | F23: =IF(C23<>"",VLOOKUP(C23,명단!$C$4:$F$90,2,FALSE),"") -> 최장열 | G23: =IF(E23="","",E23-D23) -> 4445 | H23: =IF(G23<>"",$H$7,"") -> 2420 | I23: =IF(G23<>"",G23/H23,"") -> 1.8367769 | J23: 3 | K23: =IF(C23<>"","완료","") -> 완료
B24: =B23+1 -> 18 | C24: 1027 | D24: 8270 | E24: 12560 | F24: =IF(C24<>"",VLOOKUP(C24,명단!$C$4:$F$90,2,FALSE),"") -> 안자현 | G24: =IF(E24="","",E24-D24) -> 4290 | H24: =IF(G24<>"",$H$7,"") -> 2420 | I24: =IF(G24<>"",G24/H24,"") -> 1.7727273 | J24: 3 | K24: =IF(C24<>"","완료","") -> 완료 | N24: 경남 합천군 용주면 공암길 245-260
B25: =B24+1 -> 19 | C25: 4510 | D25: 8950 | E25: 13295 | F25: =IF(C25<>"",VLOOKUP(C25,명단!$C$4:$F$90,2,FALSE),"") -> 심우철 | G25: =IF(E25="","",E25-D25) -> 4345 | H25: =IF(G25<>"",$H$7,"") -> 2420 | I25: =IF(G25<>"",G25/H25,"") -> 1.7954545 | J25: 3 | K25: =IF(C25<>"","완료","") -> 완료
B26: =B25+1 -> 20 | C26: 7000 | D26: 8775 | E26: 12925 | F26: =IF(C26<>"",VLOOKUP(C26,명단!$C$4:$F$90,2,FALSE),"") -> 허창영 | G26: =IF(E26="","",E26-D26) -> 4150 | H26: =IF(G26<>"",$H$7,"") -> 2420 | I26: =IF(G26<>"",G26/H26,"") -> 1.714876 | J26: 3 | K26: =IF(C26<>"","완료","") -> 완료 | N26: 010-8643-8959,FAX(070)4015-3999
B27: =B26+1 -> 21 | C27: 5920 | D27: 8525 | E27: 12825 | F27: =IF(C27<>"",VLOOKUP(C27,명단!$C$4:$F$90,2,FALSE),"") -> 유후근 | G27: =IF(E27="","",E27-D27) -> 4300 | H27: =IF(G27<>"",$H$7,"") -> 2420 | I27: =IF(G27<>"",G27/H27,"") -> 1.7768595 | J27: 3 | K27: =IF(C27<>"","완료","") -> 완료
B28: =B27+1 -> 22 | C28: 4156 | D28: 8565 | E28: 12705 | F28: =IF(C28<>"",VLOOKUP(C28,명단!$C$4:$F$90,2,FALSE),"") -> 배승순 | G28: =IF(E28="","",E28-D28) -> 4140 | H28: =IF(G28<>"",$H$7,"") -> 2420 | I28: =IF(G28<>"",G28/H28,"") -> 1.7107438 | J28: 3 | K28: =IF(C28<>"","완료","") -> 완료
B29: =B28+1 -> 23 | C29: 9427 | D29: 8325 | E29: 12570 | F29: =IF(C29<>"",VLOOKUP(C29,명단!$C$4:$F$90,2,FALSE),"") -> 원해종 | G29: =IF(E29="","",E29-D29) -> 4245 | H29: =IF(G29<>"",$H$7,"") -> 2420 | I29: =IF(G29<>"",G29/H29,"") -> 1.7541322 | J29: 3 | K29: =IF(C29<>"","완료","") -> 완료
B30: =B29+1 -> 24 | C30: 1041 | D30: 8445 | E30: 12680 | F30: =IF(C30<>"",VLOOKUP(C30,명단!$C$4:$F$90,2,FALSE),"") -> 이승준 | G30: =IF(E30="","",E30-D30) -> 4235 | H30: =IF(G30<>"",$H$7,"") -> 2420 | I30: =IF(G30<>"",G30/H30,"") -> 1.75 | J30: 3 | K30: =IF(C30<>"","완료","") -> 완료
B31: =B30+1 -> 25 | C31: 5619 | D31: 9070 | E31: 13325 | F31: =IF(C31<>"",VLOOKUP(C31,명단!$C$4:$F$90,2,FALSE),"") -> 송승원 | G31: =IF(E31="","",E31-D31) -> 4255 | H31: =IF(G31<>"",$H$7,"") -> 2420 | I31: =IF(G31<>"",G31/H31,"") -> 1.7582645 | J31: 6 | K31: =IF(C31<>"","완료","") -> 완료
B32: =B31+1 -> 26 | C32: 3385 | D32: 8515 | E32: 12795 | F32: =IF(C32<>"",VLOOKUP(C32,명단!$C$4:$F$90,2,FALSE),"") -> 이종래 | G32: =IF(E32="","",E32-D32) -> 4280 | H32: =IF(G32<>"",$H$7,"") -> 2420 | I32: =IF(G32<>"",G32/H32,"") -> 1.768595 | J32: 6 | K32: =IF(C32<>"","완료","") -> 완료
B33: =B32+1 -> 27 | C33: 3447 | D33: 8450 | E33: 12690 | F33: =IF(C33<>"",VLOOKUP(C33,명단!$C$4:$F$90,2,FALSE),"") -> 전봉근 | G33: =IF(E33="","",E33-D33) -> 4240 | H33: =IF(G33<>"",$H$7,"") -> 2420 | I33: =IF(G33<>"",G33/H33,"") -> 1.7520661 | J33: 6 | K33: =IF(C33<>"","완료","") -> 완료
B34: =B33+1 -> 28 | C34: 5970 | D34: 8550 | E34: 12775 | F34: =IF(C34<>"",VLOOKUP(C34,명단!$C$4:$F$90,2,FALSE),"") -> 유성희 | G34: =IF(E34="","",E34-D34) -> 4225 | H34: =IF(G34<>"",$H$7,"") -> 2420 | I34: =IF(G34<>"",G34/H34,"") -> 1.7458678 | J34: 6 | K34: =IF(C34<>"","완료","") -> 완료
B35: =B34+1 -> 29 | C35: 4550 | D35: 7900 | E35: 12140 | F35: =IF(C35<>"",VLOOKUP(C35,명단!$C$4:$F$90,2,FALSE),"") -> 윤장열 | G35: =IF(E35="","",E35-D35) -> 4240 | H35: =IF(G35<>"",$H$7,"") -> 2420 | I35: =IF(G35<>"",G35/H35,"") -> 1.7520661 | J35: 6 | K35: =IF(C35<>"","완료","") -> 완료
B36: =B35+1 -> 30 | C36: 4109 | D36: 8915 | E36: 13135 | F36: =IF(C36<>"",VLOOKUP(C36,명단!$C$4:$F$90,2,FALSE),"") -> 장성조 | G36: =IF(E36="","",E36-D36) -> 4220 | H36: =IF(G36<>"",$H$7,"") -> 2420 | I36: =IF(G36<>"",G36/H36,"") -> 1.7438017 | J36: 6 | K36: =IF(C36<>"","완료","") -> 완료
B37: 소계 | G37: =SUM(G7:G36) -> 128920 | H37: =SUM(H7:H36) -> 72600 | I37: =IF(H37<>0,G37/H37,0) -> 1.7757576
B39: 인쇄 | C39: 4109

Sheet 6
B2: ='1'!B2 -> 체리부로 26회차 출하 집계표 | L2: 체리부로 23회차 출하 집계표
B4: 46042 | F4: 31 | G4: 일령 | H4: 1.9 | I4: Kg
B6: 순번 | C6: 차량 | D6: 공차 | E6: 총중량 | F6: 기사 | G6: 중량 | H6: 수수 | I6: 평체 | J6: 계사 | K6: 소독 | L6: 비고
B7: 31 | C7: 2914 | D7: 8665 | E7: 12970 | F7: =IF(C7<>"",VLOOKUP(C7,명단!$C$4:$F$90,2,FALSE),"") -> 홍월식 | G7: =IF(E7="","",E7-D7) -> 4305 | H7: 2420 | I7: =IF(G7<>"",G7/H7,"") -> 1.7789256 | J7: 6 | K7: =IF(C7<>"","완료","") -> 완료 | N7: 계량증명서
B8: =B7+1 -> 32 | C8: 7071 | D8: 8640 | E8: 12775 | F8: =IF(C8<>"",VLOOKUP(C8,명단!$C$4:$F$90,2,FALSE),"") -> 강석호 | G8: =IF(E8="","",E8-D8) -> 4135 | H8: =IF(G8<>"",$H$7,"") -> 2420 | I8: =IF(G8<>"",G8/H8,"") -> 1.7086777 | J8: 6 | K8: =IF(C8<>"","완료","") -> 완료
B9: =B8+1 -> 33 | C9: 7126 | D9: 8150 | E9: 12335 | F9: =IF(C9<>"",VLOOKUP(C9,명단!$C$4:$F$90,2,FALSE),"") -> 전대권 | G9: =IF(E9="","",E9-D9) -> 4185 | H9: =IF(G9<>"",$H$7,"") -> 2420 | I9: =IF(G9<>"",G9/H9,"") -> 1.7293388 | J9: 6 | K9: =IF(C9<>"","완료","") -> 완료 | N9: (제출용)
B10: =B9+1 -> 34 | C10: 5562 | D10: 8095 | E10: 12230 | F10: =IF(C10<>"",VLOOKUP(C10,명단!$C$4:$F$90,2,FALSE),"") -> 오완수 | G10: =IF(E10="","",E10-D10) -> 4135 | H10: =IF(G10<>"",$H$7,"") -> 2420 | I10: =IF(G10<>"",G10/H10,"") -> 1.7086777 | J10: 6 | K10: =IF(C10<>"","완료","") -> 완료 | N10: 계량일시 | O10: =NOW() -> 46088.592
B11: =B10+1 -> 35 | C11: 5784 | D11: 7815 | E11: 12140 | F11: =IF(C11<>"",VLOOKUP(C11,명단!$C$4:$F$90,2,FALSE),"") -> 정영천 | G11: =IF(E11="","",E11-D11) -> 4325 | H11: =IF(G11<>"",$H$7,"") -> 2420 | I11: =IF(G11<>"",G11/H11,"") -> 1.7871901 | J11: 6 | K11: =IF(C11<>"","완료","") -> 완료 | N11: 차량 | O11: =C39 -> 7030 | P11: 기사명 | Q11: =VLOOKUP(O11,C7:I45,4,0) -> 이재철
B12: =B11+1 -> 36 | C12: 7030 | D12: 8670 | E12: 11430 | F12: =IF(C12<>"",VLOOKUP(C12,명단!$C$4:$F$90,2,FALSE),"") -> 이재철 | G12: =IF(E12="","",E12-D12) -> 2760 | H12: 1560 | I12: =IF(G12<>"",G12/H12,"") -> 1.7692308 | J12: 6 | K12: =IF(C12<>"","완료","") -> 완료 | N12: 거 래 처 | O12: 체리부로
F13: =IF(C13<>"",VLOOKUP(C13,명단!$C$4:$F$90,2,FALSE),"") | G13: =IF(E13="","",E13-D13) | H13: =IF(G13<>"",$H$7,"") | I13: =IF(G13<>"",G13/H13,"") | K13: =IF(C13<>"","완료","") | N13: 품명 | O13: 육계
F14: =IF(C14<>"",VLOOKUP(C14,명단!$C$4:$F$90,2,FALSE),"") | G14: =IF(E14="","",E14-D14) | H14: =IF(G14<>"",$H$7,"") | I14: =IF(G14<>"",G14/H14,"") | K14: =IF(C14<>"","완료","") | N14: 공차중량 | O14: =VLOOKUP(O11,C7:I45,2,0) -> 8670 | Q14: Kg
F15: =IF(C15<>"",VLOOKUP(C15,명단!$C$4:$F$90,2,FALSE),"") | G15: =IF(E15="","",E15-D15) | H15: =IF(G15<>"",$H$7,"") | I15: =IF(G15<>"",G15/H15,"") | K15: =IF(C15<>"","완료","") | N15: 총 중 량 | O15: =VLOOKUP(O11,C7:I45,3,0) -> 11430 | Q15: Kg
F16: =IF(C16<>"",VLOOKUP(C16,명단!$C$4:$F$90,2,FALSE),"") | G16: =IF(E16="","",E16-D16) | H16: =IF(G16<>"",$H$7,"") | I16: =IF(G16<>"",G16/H16,"") | K16: =IF(C16<>"","완료","") | N16: 실 중 량 | O16: =VLOOKUP(O11,C7:I45,5,0) -> 2760 | Q16: Kg
F17: =IF(C17<>"",VLOOKUP(C17,명단!$C$4:$F$90,2,FALSE),"") | G17: =IF(E17="","",E17-D17) | H17: =IF(G17<>"",$H$7,"") | I17: =IF(G17<>"",G17/H17,"") | K17: =IF(C17<>"","완료","") | N17: 평체 | O17: =VLOOKUP(O11,C7:I45,7,0) -> 1.7692308 | Q17: Kg
F18: =IF(C18<>"",VLOOKUP(C18,명단!$C$4:$F$90,2,FALSE),"") | G18: =IF(E18="","",E18-D18) | H18: =IF(G18<>"",$H$7,"") | I18: =IF(G18<>"",G18/H18,"") | K18: =IF(C18<>"","완료","") | N18: 수수 | O18: =VLOOKUP(O11,C7:I45,6,0) -> 1560 | Q18: 수
F19: =IF(C19<>"",VLOOKUP(C19,명단!$C$4:$F$90,2,FALSE),"") | G19: =IF(E19="","",E19-D19) | H19: =IF(G19<>"",$H$7,"") | I19: =IF(G19<>"",G19/H19,"") | K19: =IF(C19<>"","완료","")
F20: =IF(C20<>"",VLOOKUP(C20,명단!$C$4:$F$90,2,FALSE),"") | G20: =IF(E20="","",E20-D20) | H20: =IF(G20<>"",$H$7,"") | I20: =IF(G20<>"",G20/H20,"") | K20: =IF(C20<>"","완료","") | N20: 상기와 같이 계량하였음을 증명함.
F21: =IF(C21<>"",VLOOKUP(C21,명단!$C$4:$F$90,2,FALSE),"") | G21: =IF(E21="","",E21-D21) | H21: =IF(G21<>"",$H$7,"") | I21: =IF(G21<>"",G21/H21,"") | K21: =IF(C21<>"","완료","")
F22: =IF(C22<>"",VLOOKUP(C22,명단!$C$4:$F$90,2,FALSE),"") | G22: =IF(E22="","",E22-D22) | H22: =IF(G22<>"",$H$7,"") | I22: =IF(G22<>"",G22/H22,"") | K22: =IF(C22<>"","완료","") | N22: 공암산성 윤은희
F23: =IF(C23<>"",VLOOKUP(C23,명단!$C$4:$F$90,2,FALSE),"") | G23: =IF(E23="","",E23-D23) | H23: =IF(G23<>"",$H$7,"") | I23: =IF(G23<>"",G23/H23,"") | K23: =IF(C23<>"","완료","")
F24: =IF(C24<>"",VLOOKUP(C24,명단!$C$4:$F$90,2,FALSE),"") | G24: =IF(E24="","",E24-D24) | H24: =IF(G24<>"",$H$7,"") | I24: =IF(G24<>"",G24/H24,"") | K24: =IF(C24<>"","완료","") | N24: 경남 합천군 용주면 공암길 245-260
F25: =IF(C25<>"",VLOOKUP(C25,명단!$C$4:$F$90,2,FALSE),"") | G25: =IF(E25="","",E25-D25) | H25: =IF(G25<>"",$H$7,"") | I25: =IF(G25<>"",G25/H25,"") | K25: =IF(C25<>"","완료","")
F26: =IF(C26<>"",VLOOKUP(C26,명단!$C$4:$F$90,2,FALSE),"") | G26: =IF(E26="","",E26-D26) | H26: =IF(G26<>"",$H$7,"") | I26: =IF(G26<>"",G26/H26,"") | K26: =IF(C26<>"","완료","") | N26: 010-8643-8959,FAX(070)4015-3999
F27: =IF(C27<>"",VLOOKUP(C27,명단!$C$4:$F$90,2,FALSE),"") | G27: =IF(E27="","",E27-D27) | H27: =IF(G27<>"",$H$7,"") | I27: =IF(G27<>"",G27/H27,"") | K27: =IF(C27<>"","완료","")
F28: =IF(C28<>"",VLOOKUP(C28,명단!$C$4:$F$90,2,FALSE),"") | G28: =IF(E28="","",E28-D28) | H28: =IF(G28<>"",$H$7,"") | I28: =IF(G28<>"",G28/H28,"") | K28: =IF(C28<>"","완료","")
F29: =IF(C29<>"",VLOOKUP(C29,명단!$C$4:$F$90,2,FALSE),"") | G29: =IF(E29="","",E29-D29) | H29: =IF(G29<>"",$H$7,"") | I29: =IF(G29<>"",G29/H29,"") | K29: =IF(C29<>"","완료","")
F30: =IF(C30<>"",VLOOKUP(C30,명단!$C$4:$F$90,2,FALSE),"") | G30: =IF(E30="","",E30-D30) | H30: =IF(G30<>"",$H$7,"") | I30: =IF(G30<>"",G30/H30,"") | K30: =IF(C30<>"","완료","")
F31: =IF(C31<>"",VLOOKUP(C31,명단!$C$4:$F$90,2,FALSE),"") | G31: =IF(E31="","",E31-D31) | H31: =IF(G31<>"",$H$7,"") | I31: =IF(G31<>"",G31/H31,"") | K31: =IF(C31<>"","완료","")
F32: =IF(C32<>"",VLOOKUP(C32,명단!$C$4:$F$90,2,FALSE),"") | G32: =IF(E32="","",E32-D32) | H32: =IF(G32<>"",$H$7,"") | I32: =IF(G32<>"",G32/H32,"") | K32: =IF(C32<>"","완료","")
F33: =IF(C33<>"",VLOOKUP(C33,명단!$C$4:$F$90,2,FALSE),"") | G33: =IF(E33="","",E33-D33) | H33: =IF(G33<>"",$H$7,"") | I33: =IF(G33<>"",G33/H33,"") | K33: =IF(C33<>"","완료","")
F34: =IF(C34<>"",VLOOKUP(C34,명단!$C$4:$F$90,2,FALSE),"") | G34: =IF(E34="","",E34-D34) | H34: =IF(G34<>"",$H$7,"") | I34: =IF(G34<>"",G34/H34,"") | K34: =IF(C34<>"","완료","")
B35: 소계 | F35: =IF(C35<>"",VLOOKUP(C35,명단!$C$4:$F$90,2,FALSE),"") | G35: =SUM(G7:G25) -> 23845 | H35: =SUM(H7:H25) -> 13660 | I35: =IF(G35<>"",G35/H35,"") -> 1.7456076
F36: =IF(C36<>"",VLOOKUP(C36,명단!$C$4:$F$90,2,FALSE),"") | G36: =IF(E36="","",E36-D36) | H36: =IF(G36<>"",$H$7,"") | I36: =IF(G36<>"",G36/H36,"") | K36: =IF(C36<>"","완료","")
B37: 합계 | G37: =G35+'3'!G37 -> 163340 | H37: =H35+'3'!H37 -> 92660 | I37: =IF(H37<>0,G37/H37,0) -> 1.7627887
B39: 인쇄 | C39: 7030 | G39: 2760 | H39: =G39/I39 -> 1559.322 | I39: 1.77

Sheet 명단
B2: 체리부로 출하 연락처
B3: 순번 | C3: 차량번호 | D3: 기사명 | E3: 전화번호 | F3: 비고
B4: 1 | C4: 1027 | D4: 안자현 | E4: (010) 8402-4426
B5: =B4+1 -> 2 | C5: 1041 | D5: 이승준 | E5: 1054919895
B6: =B5+1 -> 3 | C6: 1071 | D6: 남성현 | E6: 1054055070
B7: =B6+1 -> 4 | C7: 1267 | D7: 김용규 | E7: 1088227706
B8: =B7+1 -> 5 | C8: 1294 | D8: 이병옥 | E8: 1044761566
B9: =B8+1 -> 6 | C9: 1340 | D9: 박근우 | E9: 1035826059
B10: =B9+1 -> 7 | C10: 1509 | D10: 김용태 | E10: 1054615865
B11: =B10+1 -> 8 | C11: 1523 | D11: 김상덕 | E11: 1054614075
B12: =B11+1 -> 9 | C12: 1992 | D12: 왕상만 | E12: 1091786857
B13: =B12+1 -> 10 | C13: 2504 | D13: 김법규 | E13: 1054025717
B14: =B13+1 -> 11 | C14: 2565 | D14: 심재응 | E14: 1054916075
B15: =B14+1 -> 12 | C15: 2914 | D15: 홍월식 | E15: 1089537556
B16: =B15+1 -> 13 | C16: 3385 | D16: 이종래 | E16: 1037476238
... B50: =B49+1 -> 47 | C50: 6219 | D50: 김흥수 | E50: 1054537608
B51: =B50+1 -> 48 | C51: 6282 | D51: 이성재 | E51: (010) 5468-9331
B52: =B51+1 -> 49 | C52: 6456 | D52: 임재경 | E52: 1044016500
B53: =B52+1 -> 50 | C53: 6524 | D53: 김호찬 | E53: 1054593824
B54: =B53+1 -> 51 | C54: 6680 | D54: 신동수 | E54: 1054493698
B55: =B54+1 -> 52 | C55: 6708 | D55: 김성훈 | E55: 1054879241
B56: =B55+1 -> 53 | C56: 6762 | D56: 안준모 | E56: 1033698759
B57: =B56+1 -> 54 | C57: 6797 | D57: 엄익수 | E57: 1067046797
B58: =B57+1 -> 55 | C58: 7000 | D58: 허창영 | E58: 1054869541
B59: =B58+1 -> 56 | C59: 7030 | D59: 이재철 | E59: (010) 4230-0338
B60: =B59+1 -> 57 | C60: 7071 | D60: 강석호 | E60: 1090111820
B61: =B60+1 -> 58 | C61: 7126 | D61: 전대권 | E61: 1088833797
B62: =B61+1 -> 59 | C62: 7160 | D62: 정근하 | E62: 1037441678
B63: =B62+1 -> 60 | C63: 7202 | D63: 김길식 | E63: 1087371521
B64: =B63+1 -> 61 | C64: 7605 | D64: 김종구 | E64: 1054613878
B65: =B64+1 -> 62 | C65: 7609 | D65: 홍은택 | E65: 1037547094
B66: =B65+1 -> 63 | C66: 8383 | D66: 엄정섭 | E66: (010) 4517-5285
B67: =B66+1 -> 64 | C67: 8712 | D67: 임종웅 | E67: 1054980781
B68: =B67+1 -> 65 | C68: 8809 | D68: 양승달 | E68: 1052031687
B69: =B68+1 -> 66 | C69: 9427 | D69: 원해종 | E69: 1093614218
B70: =B69+1 -> 67 | C70: 9448 | D70: 김길식 | E70: 1087371521
B71: =B70+1 -> 68
B72: =B71+1 -> 69
B73: =B72+1 -> 70
B74: =B73+1 -> 71
...

Sheet 일령
B2: 일령 | C2: 수수 | D2: 가중치
B3: 27 | C3: ='1'!H37 -> 42000 | D3: =C3*B3 -> 1134000
B4: 28 | C4: ='2'!H37 -> 34200 | D4: =C4*B4 -> 957600
B5: 30 | C5: ='4'!H37 -> 125600 | D5: =C5*B5 -> 3768000
B6: 31 | C6: ='6'!H37 -> 92660 | D6: =C6*B6 -> 2872460
C8: 합계 | E8: 일령
C9: =SUM(C3:C6) -> 294460 | D9: =SUM(D3:D6) -> 8732060 | E9: =D9/C9 -> 29.654486

Sheet 공차
B2: 공차 계량
B4: 순번 | C4: 차량 | D4: 공차 | E4: 비고 | G4: 순번 | H4: 차량 | I4: 공차 | J4: 비고
B5: 1 | G5: 26
B6: =B5+1 -> 2 | G6: =G5+1 -> 27
B7: =B6+1 -> 3 | G7: =G6+1 -> 28
B8: =B7+1 -> 4 | G8: =G7+1 -> 29
B9: =B8+1 -> 5 | G9: =G8+1 -> 30
B10: =B9+1 -> 6 | G10: =G9+1 -> 31
B11: =B10+1 -> 7 | G11: =G10+1 -> 32
B12: =B11+1 -> 8 | G12: =G11+1 -> 33
B13: =B12+1 -> 9 | G13: =G12+1 -> 34
B14: =B13+1 -> 10 | G14: =G13+1 -> 35
B15: =B14+1 -> 11 | G15: =G14+1 -> 36
B16: =B15+1 -> 12 | G16: =G15+1 -> 37
B17: =B16+1 -> 13 | G17: =G16+1 -> 38
... B29: =B28+1 -> 25 | G29: =G28+1 -> 50
B31: 동 | C31: 수수 | D31: 차량 | E31: 비고 | G31: 동 | H31: 수수 | I31: 차량 | J31: 비고
B32: 1 | D32: =IF(C32<>"",C32/$H$36,"") | G32: 4 | I32: =IF(H32<>"",H32/$H$36,"")
B33: 2 | D33: =IF(C33<>"",C33/$H$36,"") | G33: 5 | I33: =IF(H33<>"",H33/$H$36,"")
B34: 3 | D34: =IF(C34<>"",C34/$H$36,"") | G34: 6 | I34: =IF(H34<>"",H34/$H$36,"")
B35: 7 | D35: =IF(C35<>"",C35/$H$36,"") | G35: 8 | I35: =IF(H35<>"",H35/$H$36,"")
B36: 총수 | C36: =SUM(C32:C35,H32:H35) -> 0 | D36: =IF(C36<>"",C36/$H$36,"") -> 0 | G36: 상차 | H36: 2420
